~~~js
try {
   var a=2
   var b=f()//f()内层调用栈里面的错误 会被传到外面来,f()内部出错
   var c=a+b

}catch(e) {//recover error
console.log('error'+e)//错误会被展现在e

}

function h() {
  throw new Error('error Object')//创建一个错误对象
}
//有一类错误 try catch 捕获不到 就是语法错误
eval()//将括号里面的字符串当js代码

try{
  return 8


}catch(e) {

}finally{//无论如何都会执行
 console.log(1)
}